Workbook

Sheet Mixture of 2 Gaussian dist.
C1: 1st component | F1: Pi_1 | G1: 0.5084509
C3: Mean | D3: Variance | E3: Covariance | F3: Std. Derivation | I3: c11 | J3: c22 | K3: c12
B4: X | C4: 0.17277148 | D4: 1.2332897 | E4: 0.1860267 | F4: =SQRT(D4) -> 1.1105358 | I4: =(D5/D7)/2 -> 0.4169335 | J4: =(D4/D7)/2 -> 0.50605375 | K4: =-(E4/D7)/2 -> -0.076332032
B5: Y | C5: 0.03419084 | D5: 1.0160972 | F5: =SQRT(D5) -> 1.0080165
N6: Nb. of points | O6: 50
C7: Det | D7: =D4*D5-E4^2 -> 1.2185363 | H7: Min1 | I7: Min2 | J7: Max1 | K7: Max2 | L7: Min | M7: Max | N7: Stepsize
C8: Corr | D8: =E4/(F4*F5) -> 0.1661786 | G8: X | H8: =C4-3*F4 -> -3.1588358 | I8: =C14-3*F14 -> 0.76514424 | J8: =C4+3*F4 -> 3.5043788 | K8: =C14+3*F14 -> 6.5521138 | L8: =MIN(H8,I8) -> -3.1588358 | M8: =MAX(J8,K8) -> 6.5521138 | N8: =(M8-L8)/$O$6 -> 0.19421899
G9: Y | H9: =C5-3*F5 -> -2.9898586 | I9: =C15-3*F15 -> 1.4763472 | J9: =C5+3*F5 -> 3.0582402 | K9: =C15+3*F15 -> 6.5694748 | L9: =MIN(H9,I9) -> -2.9898586 | M9: =MAX(J9,K9) -> 6.5694748 | N9: =(M9-L9)/$O$6 -> 0.19118667
C11: 2nd component | F11: Pi_2 | G11: =1-G1 -> 0.4915491
C13: Mean | D13: Variance | E13: Covariance | F13: Std. Derivation | I13: d11 | J13: d22 | K13: d12
B14: X | C14: 3.658629 | D14: 0.93025045 | E14: -0.09940991 | F14: =SQRT(D14) -> 0.96449492 | I14: =(D15/D17)/2 -> 0.54553258 | J14: =(D14/D17)/2 -> 0.70429395 | K14: =-(E14/D17)/2 -> 0.075263385
B15: Y | C15: 4.022911 | D15: 0.72055415 | F15: =SQRT(D15) -> 0.84885461
C17: Det | D17: =D14*D15-E14^2 -> 0.66041349
C18: Corr | D18: =E14/(F14*F15) -> -0.12142173
A30: 1ST COMPONENT
B32: X | C32: 1 | D32: 2 | E32: 3 | F32: 4 | G32: 5 | H32: 6 | I32: 7 | J32: 8 | K32: 9 | L32: 10 | M32: 11 | N32: 12 | O32: 13 | P32: 14 | Q32: 15 | R32: 16 | S32: 17 | T32: 18 | U32: 19 | V32: 20 | W32: 21 | X32: 22 | Y32: 23 | Z32: 24 | AA32: 25 | AB32: 26 | AC32: 27 | AD32: 28 | AE32: 29 | AF32: 30 | AG32: 31 | AH32: 32 | AI32: 33 | AJ32: 34 | AK32: 35 | AL32: 36 | AM32: 37 | AN32: 38 | AO32: 39 | AP32: 40 | AQ32: 41 | AR32: 42 | AS32: 43 | AT32: 44 | AU32: 45 | AV32: 46 | AW32: 47 | AX32: 48 | AY32: 49 | AZ32: 50 | BA32: 51
A33: Y | C33: =$L$8 -> -3.1588358 | D33: =$C$33+$N$8*(D32-1) -> -2.9646168 | E33: =$C$33+$N$8*(E32-1) -> -2.7703979 | F33: =$C$33+$N$8*(F32-1) -> -2.5761789 | G33: =$C$33+$N$8*(G32-1) -> -2.3819599 | H33: =$C$33+$N$8*(H32-1) -> -2.1877409 | I33: =$C$33+$N$8*(I32-1) -> -1.9935219 | J33: =$C$33+$N$8*(J32-1) -> -1.7993029 | K33: =$C$33+$N$8*(K32-1) -> -1.6050839 | ... BA33: =$C$33+$N$8*(BA32-1) -> 6.5521138
A34: 1 | B34: =$H$9 -> -2.9898586 | C34: =SQRT($I$4*$J$4-$K$4^2)/PI()*EXP(-($I$4*((C$33-$C$4)^2)+2*$K$4*(C$33-$C$4)*($B34-$C$5)+$J$4*(($B34-$C$5)^2))) -> 6.4154488e-05 | D34: =SQRT($I$4*$J$4-$K$4^2)/PI()*EXP(-($I$4*((D$33-$C$4)^2)+2*$K$4*(D$33-$C$4)*($B34-$C$5)+$J$4*(($B34-$C$5)^2))) -> 9.9034295e-05 | E34: =SQRT($I$4*$J$4-$K$4^2)/PI()*EXP(-($I$4*((E$33-$C$4)^2)+2*$K$4*(E$33-$C$4)*($B34-$C$5)+$J$4*(($B34-$C$5)^2))) -> 0.00014814389 | F34: =SQRT($I$4*$J$4-$K$4^2)/PI()*EXP(-($I$4*((F$33-$C$4)^2)+2*$K$4*(F$33-$C$4)*($B34-$C$5)+$J$4*(($B34-$C$5)^2))) -> 0.00021474421 | G34: =SQRT($I$4*$J$4-$K$4^2)/PI()*EXP(-($I$4*((G$33-$C$4)^2)+2*$K$4*(G$33-$C$4)*($B34-$C$5)+$J$4*(($B34-$C$5)^2))) -> 0.0003016468 | H34: =SQRT($I$4*$J$4-$K$4^2)/PI()*EXP(-($I$4*((H$33-$C$4)^2)+2*$K$4*(H$33-$C$4)*($B34-$C$5)+$J$4*(($B34-$C$5)^2))) -> 0.0004105968 | I34: =SQRT($I$4*$J$4-$K$4^2)/PI()*EXP(-($I$4*((I$33-$C$4)^2)+2*$K$4*(I$33-$C$4)*($B34-$C$5)+$J$4*(($B34-$C$5)^2))) -> 0.00054159165 | J34: =SQRT($I$4*$J$4-$K$4^2)/PI()*EXP(-($I$4*((J$33-$C$4)^2)+2*$K$4*(J$33-$C$4)*($B34-$C$5)+$J$4*(($B34-$C$5)^2))) -> 0.00069225792 | ... BA34: =SQRT($I$4*$J$4-$K$4^2)/PI()*EXP(-($I$4*((BA$33-$C$4)^2)+2*$K$4*(BA$33-$C$4)*($B34-$C$5)+$J$4*(($B34-$C$5)^2))) -> 3.1704735e-12
A35: 2 | B35: =$B$34+$N$9*(A35-1) -> -2.7986719 | C35: =SQRT($I$4*$J$4-$K$4^2)/PI()*EXP(-($I$4*((C$33-$C$4)^2)+2*$K$4*(C$33-$C$4)*($B35-$C$5)+$J$4*(($B35-$C$5)^2))) -> 0.00010258727 | D35: =SQRT($I$4*$J$4-$K$4^2)/PI()*EXP(-($I$4*((D$33-$C$4)^2)+2*$K$4*(D$33-$C$4)*($B35-$C$5)+$J$4*(($B35-$C$5)^2))) -> 0.00015926265 | E35: =SQRT($I$4*$J$4-$K$4^2)/PI()*EXP(-($I$4*((E$33-$C$4)^2)+2*$K$4*(E$33-$C$4)*($B35-$C$5)+$J$4*(($B35-$C$5)^2))) -> 0.00023959292 | F35: =SQRT($I$4*$J$4-$K$4^2)/PI()*EXP(-($I$4*((F$33-$C$4)^2)+2*$K$4*(F$33-$C$4)*($B35-$C$5)+$J$4*(($B35-$C$5)^2))) -> 0.00034927989 | G35: =SQRT($I$4*$J$4-$K$4^2)/PI()*EXP(-($I$4*((G$33-$C$4)^2)+2*$K$4*(G$33-$C$4)*($B35-$C$5)+$J$4*(($B35-$C$5)^2))) -> 0.00049341546 | H35: =SQRT($I$4*$J$4-$K$4^2)/PI()*EXP(-($I$4*((H$33-$C$4)^2)+2*$K$4*(H$33-$C$4)*($B35-$C$5)+$J$4*(($B35-$C$5)^2))) -> 0.00067544733 | I35: =SQRT($I$4*$J$4-$K$4^2)/PI()*EXP(-($I$4*((I$33-$C$4)^2)+2*$K$4*(I$33-$C$4)*($B35-$C$5)+$J$4*(($B35-$C$5)^2))) -> 0.00089600367 | J35: =SQRT($I$4*$J$4-$K$4^2)/PI()*EXP(-($I$4*((J$33-$C$4)^2)+2*$K$4*(J$33-$C$4)*($B35-$C$5)+$J$4*(($B35-$C$5)^2))) -> 0.001151775 | ... BA35: =SQRT($I$4*$J$4-$K$4^2)/PI()*EXP(-($I$4*((BA$33-$C$4)^2)+2*$K$4*(BA$33-$C$4)*($B35-$C$5)+$J$4*(($B35-$C$5)^2))) -> 6.7310925e-12
A36: 3 | B36: =$B$34+$N$9*(A36-1) -> -2.6074852 | C36: =SQRT($I$4*$J$4-$K$4^2)/PI()*EXP(-($I$4*((C$33-$C$4)^2)+2*$K$4*(C$33-$C$4)*($B36-$C$5)+$J$4*(($B36-$C$5)^2))) -> 0.00015808593 | D36: =SQRT($I$4*$J$4-$K$4^2)/PI()*EXP(-($I$4*((D$33-$C$4)^2)+2*$K$4*(D$33-$C$4)*($B36-$C$5)+$J$4*(($B36-$C$5)^2))) -> 0.00024681729 | E36: =SQRT($I$4*$J$4-$K$4^2)/PI()*EXP(-($I$4*((E$33-$C$4)^2)+2*$K$4*(E$33-$C$4)*($B36-$C$5)+$J$4*(($B36-$C$5)^2))) -> 0.00037341995 | F36: =SQRT($I$4*$J$4-$K$4^2)/PI()*EXP(-($I$4*((F$33-$C$4)^2)+2*$K$4*(F$33-$C$4)*($B36-$C$5)+$J$4*(($B36-$C$5)^2))) -> 0.00054746836 | G36: =SQRT($I$4*$J$4-$K$4^2)/PI()*EXP(-($I$4*((G$33-$C$4)^2)+2*$K$4*(G$33-$C$4)*($B36-$C$5)+$J$4*(($B36-$C$5)^2))) -> 0.00077778595 | H36: =SQRT($I$4*$J$4-$K$4^2)/PI()*EXP(-($I$4*((H$33-$C$4)^2)+2*$K$4*(H$33-$C$4)*($B36-$C$5)+$J$4*(($B36-$C$5)^2))) -> 0.0010707812 | I36: =SQRT($I$4*$J$4-$K$4^2)/PI()*EXP(-($I$4*((I$33-$C$4)^2)+2*$K$4*(I$33-$C$4)*($B36-$C$5)+$J$4*(($B36-$C$5)^2))) -> 0.0014285023 | J36: =SQRT($I$4*$J$4-$K$4^2)/PI()*EXP(-($I$4*((J$33-$C$4)^2)+2*$K$4*(J$33-$C$4)*($B36-$C$5)+$J$4*(($B36-$C$5)^2))) -> 0.0018467185 | ... BA36: =SQRT($I$4*$J$4-$K$4^2)/PI()*EXP(-($I$4*((BA$33-$C$4)^2)+2*$K$4*(BA$33-$C$4)*($B36-$C$5)+$J$4*(($B36-$C$5)^2))) -> 1.377147e-11
A37: 4 | B37: =$B$34+$N$9*(A37-1) -> -2.4162986 | C37: =SQRT($I$4*$J$4-$K$4^2)/PI()*EXP(-($I$4*((C$33-$C$4)^2)+2*$K$4*(C$33-$C$4)*($B37-$C$5)+$J$4*(($B37-$C$5)^2))) -> 0.00023476117 | D37: =SQRT($I$4*$J$4-$K$4^2)/PI()*EXP(-($I$4*((D$33-$C$4)^2)+2*$K$4*(D$33-$C$4)*($B37-$C$5)+$J$4*(($B37-$C$5)^2))) -> 0.00036861291 | E37: =SQRT($I$4*$J$4-$K$4^2)/PI()*EXP(-($I$4*((E$33-$C$4)^2)+2*$K$4*(E$33-$C$4)*($B37-$C$5)+$J$4*(($B37-$C$5)^2))) -> 0.00056085989 | F37: =SQRT($I$4*$J$4-$K$4^2)/PI()*EXP(-($I$4*((F$33-$C$4)^2)+2*$K$4*(F$33-$C$4)*($B37-$C$5)+$J$4*(($B37-$C$5)^2))) -> 0.00082694721 | G37: =SQRT($I$4*$J$4-$K$4^2)/PI()*EXP(-($I$4*((G$33-$C$4)^2)+2*$K$4*(G$33-$C$4)*($B37-$C$5)+$J$4*(($B37-$C$5)^2))) -> 0.0011815191 | H37: =SQRT($I$4*$J$4-$K$4^2)/PI()*EXP(-($I$4*((H$33-$C$4)^2)+2*$K$4*(H$33-$C$4)*($B37-$C$5)+$J$4*(($B37-$C$5)^2))) -> 0.0016358493 | I37: =SQRT($I$4*$J$4-$K$4^2)/PI()*EXP(-($I$4*((I$33-$C$4)^2)+2*$K$4*(I$33-$C$4)*($B37-$C$5)+$J$4*(($B37-$C$5)^2))) -> 0.0021947517 | J37: =SQRT($I$4*$J$4-$K$4^2)/PI()*EXP(-($I$4*((J$33-$C$4)^2)+2*$K$4*(J$33-$C$4)*($B37-$C$5)+$J$4*(($B37-$C$5)^2))) -> 0.002853429 | ... BA37: =SQRT($I$4*$J$4-$K$4^2)/PI()*EXP(-($I$4*((BA$33-$C$4)^2)+2*$K$4*(BA$33-$C$4)*($B37-$C$5)+$J$4*(($B37-$C$5)^2))) -> 2.715241e-11
A38: 5 | B38: =$B$34+$N$9*(A38-1) -> -2.2251119 | C38: =SQRT($I$4*$J$4-$K$4^2)/PI()*EXP(-($I$4*((C$33-$C$4)^2)+2*$K$4*(C$33-$C$4)*($B38-$C$5)+$J$4*(($B38-$C$5)^2))) -> 0.00033596393 | D38: =SQRT($I$4*$J$4-$K$4^2)/PI()*EXP(-($I$4*((D$33-$C$4)^2)+2*$K$4*(D$33-$C$4)*($B38-$C$5)+$J$4*(($B38-$C$5)^2))) -> 0.00053051642 | E38: =SQRT($I$4*$J$4-$K$4^2)/PI()*EXP(-($I$4*((E$33-$C$4)^2)+2*$K$4*(E$33-$C$4)*($B38-$C$5)+$J$4*(($B38-$C$5)^2))) -> 0.00081179162 | F38: =SQRT($I$4*$J$4-$K$4^2)/PI()*EXP(-($I$4*((F$33-$C$4)^2)+2*$K$4*(F$33-$C$4)*($B38-$C$5)+$J$4*(($B38-$C$5)^2))) -> 0.0012037322 | G38: =SQRT($I$4*$J$4-$K$4^2)/PI()*EXP(-($I$4*((G$33-$C$4)^2)+2*$K$4*(G$33-$C$4)*($B38-$C$5)+$J$4*(($B38-$C$5)^2))) -> 0.0017296361 | H38: =SQRT($I$4*$J$4-$K$4^2)/PI()*EXP(-($I$4*((H$33-$C$4)^2)+2*$K$4*(H$33-$C$4)*($B38-$C$5)+$J$4*(($B38-$C$5)^2))) -> 0.0024083476 | I38: =SQRT($I$4*$J$4-$K$4^2)/PI()*EXP(-($I$4*((I$33-$C$4)^2)+2*$K$4*(I$33-$C$4)*($B38-$C$5)+$J$4*(($B38-$C$5)^2))) -> 0.0032495497 | J38: =SQRT($I$4*$J$4-$K$4^2)/PI()*EXP(-($I$4*((J$33-$C$4)^2)+2*$K$4*(J$33-$C$4)*($B38-$C$5)+$J$4*(($B38-$C$5)^2))) -> 0.0042488045 | ... BA38: =SQRT($I$4*$J$4-$K$4^2)/PI()*EXP(-($I$4*((BA$33-$C$4)^2)+2*$K$4*(BA$33-$C$4)*($B38-$C$5)+$J$4*(($B38-$C$5)^2))) -> 5.1590504e-11
A39: 6 | B39: =$B$34+$N$9*(A39-1) -> -2.0339252 | C39: =SQRT($I$4*$J$4-$K$4^2)/PI()*EXP(-($I$4*((C$33-$C$4)^2)+2*$K$4*(C$33-$C$4)*($B39-$C$5)+$J$4*(($B39-$C$5)^2))) -> 0.00046333206 | D39: =SQRT($I$4*$J$4-$K$4^2)/PI()*EXP(-($I$4*((D$33-$C$4)^2)+2*$K$4*(D$33-$C$4)*($B39-$C$5)+$J$4*(($B39-$C$5)^2))) -> 0.00073580109 | E39: =SQRT($I$4*$J$4-$K$4^2)/PI()*EXP(-($I$4*((E$33-$C$4)^2)+2*$K$4*(E$33-$C$4)*($B39-$C$5)+$J$4*(($B39-$C$5)^2))) -> 0.0011323171 | F39: =SQRT($I$4*$J$4-$K$4^2)/PI()*EXP(-($I$4*((F$33-$C$4)^2)+2*$K$4*(F$33-$C$4)*($B39-$C$5)+$J$4*(($B39-$C$5)^2))) -> 0.0016885552 | G39: =SQRT($I$4*$J$4-$K$4^2)/PI()*EXP(-($I$4*((G$33-$C$4)^2)+2*$K$4*(G$33-$C$4)*($B39-$C$5)+$J$4*(($B39-$C$5)^2))) -> 0.0024400686 | H39: =SQRT($I$4*$J$4-$K$4^2)/PI()*EXP(-($I$4*((H$33-$C$4)^2)+2*$K$4*(H$33-$C$4)*($B39-$C$5)+$J$4*(($B39-$C$5)^2))) -> 0.0034168694 | I39: =SQRT($I$4*$J$4-$K$4^2)/PI()*EXP(-($I$4*((I$33-$C$4)^2)+2*$K$4*(I$33-$C$4)*($B39-$C$5)+$J$4*(($B39-$C$5)^2))) -> 0.0046365429 | J39: =SQRT($I$4*$J$4-$K$4^2)/PI()*EXP(-($I$4*((J$33-$C$4)^2)+2*$K$4*(J$33-$C$4)*($B39-$C$5)+$J$4*(($B39-$C$5)^2))) -> 0.0060967692 | ... BA39: =SQRT($I$4*$J$4-$K$4^2)/PI()*EXP(-($I$4*((BA$33-$C$4)^2)+2*$K$4*(BA$33-$C$4)*($B39-$C$5)+$J$4*(($B39-$C$5)^2))) -> 9.4463596e-11
A40: 7 | B40: =$B$34+$N$9*(A40-1) -> -1.8427386 | C40: =SQRT($I$4*$J$4-$K$4^2)/PI()*EXP(-($I$4*((C$33-$C$4)^2)+2*$K$4*(C$33-$C$4)*($B40-$C$5)+$J$4*(($B40-$C$5)^2))) -> 0.00061577971 | D40: =SQRT($I$4*$J$4-$K$4^2)/PI()*EXP(-($I$4*((D$33-$C$4)^2)+2*$K$4*(D$33-$C$4)*($B40-$C$5)+$J$4*(($B40-$C$5)^2))) -> 0.00098345694 | E40: =SQRT($I$4*$J$4-$K$4^2)/PI()*EXP(-($I$4*((E$33-$C$4)^2)+2*$K$4*(E$33-$C$4)*($B40-$C$5)+$J$4*(($B40-$C$5)^2))) -> 0.0015220359 | F40: =SQRT($I$4*$J$4-$K$4^2)/PI()*EXP(-($I$4*((F$33-$C$4)^2)+2*$K$4*(F$33-$C$4)*($B40-$C$5)+$J$4*(($B40-$C$5)^2))) -> 0.002282622 | G40: =SQRT($I$4*$J$4-$K$4^2)/PI()*EXP(-($I$4*((G$33-$C$4)^2)+2*$K$4*(G$33-$C$4)*($B40-$C$5)+$J$4*(($B40-$C$5)^2))) -> 0.0033172841 | H40: =SQRT($I$4*$J$4-$K$4^2)/PI()*EXP(-($I$4*((H$33-$C$4)^2)+2*$K$4*(H$33-$C$4)*($B40-$C$5)+$J$4*(($B40-$C$5)^2))) -> 0.0046716565 | I40: =SQRT($I$4*$J$4-$K$4^2)/PI()*EXP(-($I$4*((I$33-$C$4)^2)+2*$K$4*(I$33-$C$4)*($B40-$C$5)+$J$4*(($B40-$C$5)^2))) -> 0.0063752718 | J40: =SQRT($I$4*$J$4-$K$4^2)/PI()*EXP(-($I$4*((J$33-$C$4)^2)+2*$K$4*(J$33-$C$4)*($B40-$C$5)+$J$4*(($B40-$C$5)^2))) -> 0.0084307473 | ... BA40: =SQRT($I$4*$J$4-$K$4^2)/PI()*EXP(-($I$4*((BA$33-$C$4)^2)+2*$K$4*(BA$33-$C$4)*($B40-$C$5)+$J$4*(($B40-$C$5)^2))) -> 1.6668346e-10
A41: 8 | B41: =$B$34+$N$9*(A41-1) -> -1.6515519 | C41: =SQRT($I$4*$J$4-$K$4^2)/PI()*EXP(-($I$4*((C$33-$C$4)^2)+2*$K$4*(C$33-$C$4)*($B41-$C$5)+$J$4*(($B41-$C$5)^2))) -> 0.00078866346 | D41: =SQRT($I$4*$J$4-$K$4^2)/PI()*EXP(-($I$4*((D$33-$C$4)^2)+2*$K$4*(D$33-$C$4)*($B41-$C$5)+$J$4*(($B41-$C$5)^2))) -> 0.0012667286 | E41: =SQRT($I$4*$J$4-$K$4^2)/PI()*EXP(-($I$4*((E$33-$C$4)^2)+2*$K$4*(E$33-$C$4)*($B41-$C$5)+$J$4*(($B41-$C$5)^2))) -> 0.0019715828 | F41: =SQRT($I$4*$J$4-$K$4^2)/PI()*EXP(-($I$4*((F$33-$C$4)^2)+2*$K$4*(F$33-$C$4)*($B41-$C$5)+$J$4*(($B41-$C$5)^2))) -> 0.0029736239 | G41: =SQRT($I$4*$J$4-$K$4^2)/PI()*EXP(-($I$4*((G$33-$C$4)^2)+2*$K$4*(G$33-$C$4)*($B41-$C$5)+$J$4*(($B41-$C$5)^2))) -> 0.0043460689 | H41: =SQRT($I$4*$J$4-$K$4^2)/PI()*EXP(-($I$4*((H$33-$C$4)^2)+2*$K$4*(H$33-$C$4)*($B41-$C$5)+$J$4*(($B41-$C$5)^2))) -> 0.0061552648 | I41: =SQRT($I$4*$J$4-$K$4^2)/PI()*EXP(-($I$4*((I$33-$C$4)^2)+2*$K$4*(I$33-$C$4)*($B41-$C$5)+$J$4*(($B41-$C$5)^2))) -> 0.0084476604 | J41: =SQRT($I$4*$J$4-$K$4^2)/PI()*EXP(-($I$4*((J$33-$C$4)^2)+2*$K$4*(J$33-$C$4)*($B41-$C$5)+$J$4*(($B41-$C$5)^2))) -> 0.01123481 | ... BA41: =SQRT($I$4*$J$4-$K$4^2)/PI()*EXP(-($I$4*((BA$33-$C$4)^2)+2*$K$4*(BA$33-$C$4)*($B41-$C$5)+$J$4*(($B41-$C$5)^2))) -> 2.8343524e-10
A42: 9 | B42: =$B$34+$N$9*(A42-1) -> -1.4603652 | C42: =SQRT($I$4*$J$4-$K$4^2)/PI()*EXP(-($I$4*((C$33-$C$4)^2)+2*$K$4*(C$33-$C$4)*($B42-$C$5)+$J$4*(($B42-$C$5)^2))) -> 0.00097340008 | D42: =SQRT($I$4*$J$4-$K$4^2)/PI()*EXP(-($I$4*((D$33-$C$4)^2)+2*$K$4*(D$33-$C$4)*($B42-$C$5)+$J$4*(($B42-$C$5)^2))) -> 0.0015723353 | E42: =SQRT($I$4*$J$4-$K$4^2)/PI()*EXP(-($I$4*((E$33-$C$4)^2)+2*$K$4*(E$33-$C$4)*($B42-$C$5)+$J$4*(($B42-$C$5)^2))) -> 0.0024611523 | F42: =SQRT($I$4*$J$4-$K$4^2)/PI()*EXP(-($I$4*((F$33-$C$4)^2)+2*$K$4*(F$33-$C$4)*($B42-$C$5)+$J$4*(($B42-$C$5)^2))) -> 0.0037331152 | G42: =SQRT($I$4*$J$4-$K$4^2)/PI()*EXP(-($I$4*((G$33-$C$4)^2)+2*$K$4*(G$33-$C$4)*($B42-$C$5)+$J$4*(($B42-$C$5)^2))) -> 0.0054871125 | H42: =SQRT($I$4*$J$4-$K$4^2)/PI()*EXP(-($I$4*((H$33-$C$4)^2)+2*$K$4*(H$33-$C$4)*($B42-$C$5)+$J$4*(($B42-$C$5)^2))) -> 0.0078154845 | I42: =SQRT($I$4*$J$4-$K$4^2)/PI()*EXP(-($I$4*((I$33-$C$4)^2)+2*$K$4*(I$33-$C$4)*($B42-$C$5)+$J$4*(($B42-$C$5)^2))) -> 0.01078717 | J42: =SQRT($I$4*$J$4-$K$4^2)/PI()*EXP(-($I$4*((J$33-$C$4)^2)+2*$K$4*(J$33-$C$4)*($B42-$C$5)+$J$4*(($B42-$C$5)^2))) -> 0.014427752 | ... BA42: =SQRT($I$4*$J$4-$K$4^2)/PI()*EXP(-($I$4*((BA$33-$C$4)^2)+2*$K$4*(BA$33-$C$4)*($B42-$C$5)+$J$4*(($B42-$C$5)^2))) -> 4.6446021e-10
A43: 10 | B43: =$B$34+$N$9*(A43-1) -> -1.2691786 | C43: =SQRT($I$4*$J$4-$K$4^2)/PI()*EXP(-($I$4*((C$33-$C$4)^2)+2*$K$4*(C$33-$C$4)*($B43-$C$5)+$J$4*(($B43-$C$5)^2))) -> 0.0011577755 | D43: =SQRT($I$4*$J$4-$K$4^2)/PI()*EXP(-($I$4*((D$33-$C$4)^2)+2*$K$4*(D$33-$C$4)*($B43-$C$5)+$J$4*(($B43-$C$5)^2))) -> 0.0018807888 | E43: =SQRT($I$4*$J$4-$K$4^2)/PI()*EXP(-($I$4*((E$33-$C$4)^2)+2*$K$4*(E$33-$C$4)*($B43-$C$5)+$J$4*(($B43-$C$5)^2))) -> 0.0029607059 | F43: =SQRT($I$4*$J$4-$K$4^2)/PI()*EXP(-($I$4*((F$33-$C$4)^2)+2*$K$4*(F$33-$C$4)*($B43-$C$5)+$J$4*(($B43-$C$5)^2))) -> 0.0045163758 | G43: =SQRT($I$4*$J$4-$K$4^2)/PI()*EXP(-($I$4*((G$33-$C$4)^2)+2*$K$4*(G$33-$C$4)*($B43-$C$5)+$J$4*(($B43-$C$5)^2))) -> 0.0066761248 | H43: =SQRT($I$4*$J$4-$K$4^2)/PI()*EXP(-($I$4*((H$33-$C$4)^2)+2*$K$4*(H$33-$C$4)*($B43-$C$5)+$J$4*(($B43-$C$5)^2))) -> 0.0095630931 | I43: =SQRT($I$4*$J$4-$K$4^2)/PI()*EXP(-($I$4*((I$33-$C$4)^2)+2*$K$4*(I$33-$C$4)*($B43-$C$5)+$J$4*(($B43-$C$5)^2))) -> 0.013274308 | J43: =SQRT($I$4*$J$4-$K$4^2)/PI()*EXP(-($I$4*((J$33-$C$4)^2)+2*$K$4*(J$33-$C$4)*($B43-$C$5)+$J$4*(($B43-$C$5)^2))) -> 0.01785521 | ... BA43: =SQRT($I$4*$J$4-$K$4^2)/PI()*EXP(-($I$4*((BA$33-$C$4)^2)+2*$K$4*(BA$33-$C$4)*($B43-$C$5)+$J$4*(($B43-$C$5)^2))) -> 7.3346011e-10
A44: 11 | B44: =$B$34+$N$9*(A44-1) -> -1.0779919 | C44: =SQRT($I$4*$J$4-$K$4^2)/PI()*EXP(-($I$4*((C$33-$C$4)^2)+2*$K$4*(C$33-$C$4)*($B44-$C$5)+$J$4*(($B44-$C$5)^2))) -> 0.0013270603 | D44: =SQRT($I$4*$J$4-$K$4^2)/PI()*EXP(-($I$4*((D$33-$C$4)^2)+2*$K$4*(D$33-$C$4)*($B44-$C$5)+$J$4*(($B44-$C$5)^2))) -> 0.0021680447 | E44: =SQRT($I$4*$J$4-$K$4^2)/PI()*EXP(-($I$4*((E$33-$C$4)^2)+2*$K$4*(E$33-$C$4)*($B44-$C$5)+$J$4*(($B44-$C$5)^2))) -> 0.003432301 | F44: =SQRT($I$4*$J$4-$K$4^2)/PI()*EXP(-($I$4*((F$33-$C$4)^2)+2*$K$4*(F$33-$C$4)*($B44-$C$5)+$J$4*(($B44-$C$5)^2))) -> 0.0052655298 | G44: =SQRT($I$4*$J$4-$K$4^2)/PI()*EXP(-($I$4*((G$33-$C$4)^2)+2*$K$4*(G$33-$C$4)*($B44-$C$5)+$J$4*(($B44-$C$5)^2))) -> 0.0078277752 | H44: =SQRT($I$4*$J$4-$K$4^2)/PI()*EXP(-($I$4*((H$33-$C$4)^2)+2*$K$4*(H$33-$C$4)*($B44-$C$5)+$J$4*(($B44-$C$5)^2))) -> 0.011276496 | I44: =SQRT($I$4*$J$4-$K$4^2)/PI()*EXP(-($I$4*((I$33-$C$4)^2)+2*$K$4*(I$33-$C$4)*($B44-$C$5)+$J$4*(($B44-$C$5)^2))) -> 0.015741626 | J44: =SQRT($I$4*$J$4-$K$4^2)/PI()*EXP(-($I$4*((J$33-$C$4)^2)+2*$K$4*(J$33-$C$4)*($B44-$C$5)+$J$4*(($B44-$C$5)^2))) -> 0.021294358 | ... BA44: =SQRT($I$4*$J$4-$K$4^2)/PI()*EXP(-($I$4*((BA$33-$C$4)^2)+2*$K$4*(BA$33-$C$4)*($B44-$C$5)+$J$4*(($B44-$C$5)^2))) -> 1.1161892e-09
A45: 12 | B45: =$B$34+$N$9*(A45-1) -> -0.88680522 | C45: =SQRT($I$4*$J$4-$K$4^2)/PI()*EXP(-($I$4*((C$33-$C$4)^2)+2*$K$4*(C$33-$C$4)*($B45-$C$5)+$J$4*(($B45-$C$5)^2))) -> 0.0014658525 | D45: =SQRT($I$4*$J$4-$K$4^2)/PI()*EXP(-($I$4*((D$33-$C$4)^2)+2*$K$4*(D$33-$C$4)*($B45-$C$5)+$J$4*(($B45-$C$5)^2))) -> 0.0024084063 | E45: =SQRT($I$4*$J$4-$K$4^2)/PI()*EXP(-($I$4*((E$33-$C$4)^2)+2*$K$4*(E$33-$C$4)*($B45-$C$5)+$J$4*(($B45-$C$5)^2))) -> 0.0038345004 | F45: =SQRT($I$4*$J$4-$K$4^2)/PI()*EXP(-($I$4*((F$33-$C$4)^2)+2*$K$4*(F$33-$C$4)*($B45-$C$5)+$J$4*(($B45-$C$5)^2))) -> 0.0059159895 | G45: =SQRT($I$4*$J$4-$K$4^2)/PI()*EXP(-($I$4*((G$33-$C$4)^2)+2*$K$4*(G$33-$C$4)*($B45-$C$5)+$J$4*(($B45-$C$5)^2))) -> 0.00884475 | H45: =SQRT($I$4*$J$4-$K$4^2)/PI()*EXP(-($I$4*((H$33-$C$4)^2)+2*$K$4*(H$33-$C$4)*($B45-$C$5)+$J$4*(($B45-$C$5)^2))) -> 0.012813958 | I45: =SQRT($I$4*$J$4-$K$4^2)/PI()*EXP(-($I$4*((I$33-$C$4)^2)+2*$K$4*(I$33-$C$4)*($B45-$C$5)+$J$4*(($B45-$C$5)^2))) -> 0.017989563 | J45: =SQRT($I$4*$J$4-$K$4^2)/PI()*EXP(-($I$4*((J$33-$C$4)^2)+2*$K$4*(J$33-$C$4)*($B45-$C$5)+$J$4*(($B45-$C$5)^2))) -> 0.024473578 | ... BA45: =SQRT($I$4*$J$4-$K$4^2)/PI()*EXP(-($I$4*((BA$33-$C$4)^2)+2*$K$4*(BA$33-$C$4)*($B45-$C$5)+$J$4*(($B45-$C$5)^2))) -> 1.6369388e-09
A46: 13 | B46: =$B$34+$N$9*(A46-1) -> -0.69561855 | C46: =SQRT($I$4*$J$4-$K$4^2)/PI()*EXP(-($I$4*((C$33-$C$4)^2)+2*$K$4*(C$33-$C$4)*($B46-$C$5)+$J$4*(($B46-$C$5)^2))) -> 0.0015603543 | D46: =SQRT($I$4*$J$4-$K$4^2)/PI()*EXP(-($I$4*((D$33-$C$4)^2)+2*$K$4*(D$33-$C$4)*($B46-$C$5)+$J$4*(($B46-$C$5)^2))) -> 0.0025782474 | E46: =SQRT($I$4*$J$4-$K$4^2)/PI()*EXP(-($I$4*((E$33-$C$4)^2)+2*$K$4*(E$33-$C$4)*($B46-$C$5)+$J$4*(($B46-$C$5)^2))) -> 0.0041282456 | F46: =SQRT($I$4*$J$4-$K$4^2)/PI()*EXP(-($I$4*((F$33-$C$4)^2)+2*$K$4*(F$33-$C$4)*($B46-$C$5)+$J$4*(($B46-$C$5)^2))) -> 0.0064053967 | G46: =SQRT($I$4*$J$4-$K$4^2)/PI()*EXP(-($I$4*((G$33-$C$4)^2)+2*$K$4*(G$33-$C$4)*($B46-$C$5)+$J$4*(($B46-$C$5)^2))) -> 0.0096308829 | H46: =SQRT($I$4*$J$4-$K$4^2)/PI()*EXP(-($I$4*((H$33-$C$4)^2)+2*$K$4*(H$33-$C$4)*($B46-$C$5)+$J$4*(($B46-$C$5)^2))) -> 0.014032199 | I46: =SQRT($I$4*$J$4-$K$4^2)/PI()*EXP(-($I$4*((I$33-$C$4)^2)+2*$K$4*(I$33-$C$4)*($B46-$C$5)+$J$4*(($B46-$C$5)^2))) -> 0.019811846 | J46: =SQRT($I$4*$J$4-$K$4^2)/PI()*EXP(-($I$4*((J$33-$C$4)^2)+2*$K$4*(J$33-$C$4)*($B46-$C$5)+$J$4*(($B46-$C$5)^2))) -> 0.027105893 | ... BA46: =SQRT($I$4*$J$4-$K$4^2)/PI()*EXP(-($I$4*((BA$33-$C$4)^2)+2*$K$4*(BA$33-$C$4)*($B46-$C$5)+$J$4*(($B46-$C$5)^2))) -> 2.3134514e-09
... A84: 51 | B84: =$B$34+$N$9*(A84-1) -> 6.5694748 | C84: =SQRT($I$4*$J$4-$K$4^2)/PI()*EXP(-($I$4*((C$33-$C$4)^2)+2*$K$4*(C$33-$C$4)*($B84-$C$5)+$J$4*(($B84-$C$5)^2))) -> 2.0838406e-14 | D84: =SQRT($I$4*$J$4-$K$4^2)/PI()*EXP(-($I$4*((D$33-$C$4)^2)+2*$K$4*(D$33-$C$4)*($B84-$C$5)+$J$4*(($B84-$C$5)^2))) -> 4.2708869e-14 | E84: =SQRT($I$4*$J$4-$K$4^2)/PI()*EXP(-($I$4*((E$33-$C$4)^2)+2*$K$4*(E$33-$C$4)*($B84-$C$5)+$J$4*(($B84-$C$5)^2))) -> 8.4822529e-14 | F84: =SQRT($I$4*$J$4-$K$4^2)/PI()*EXP(-($I$4*((F$33-$C$4)^2)+2*$K$4*(F$33-$C$4)*($B84-$C$5)+$J$4*(($B84-$C$5)^2))) -> 1.6324652e-13 | G84: =SQRT($I$4*$J$4-$K$4^2)/PI()*EXP(-($I$4*((G$33-$C$4)^2)+2*$K$4*(G$33-$C$4)*($B84-$C$5)+$J$4*(($B84-$C$5)^2))) -> 3.0445016e-13 | H84: =SQRT($I$4*$J$4-$K$4^2)/PI()*EXP(-($I$4*((H$33-$C$4)^2)+2*$K$4*(H$33-$C$4)*($B84-$C$5)+$J$4*(($B84-$C$5)^2))) -> 5.5020945e-13 | I84: =SQRT($I$4*$J$4-$K$4^2)/PI()*EXP(-($I$4*((I$33-$C$4)^2)+2*$K$4*(I$33-$C$4)*($B84-$C$5)+$J$4*(($B84-$C$5)^2))) -> 9.6356153e-13 | J84: =SQRT($I$4*$J$4-$K$4^2)/PI()*EXP(-($I$4*((J$33-$C$4)^2)+2*$K$4*(J$33-$C$4)*($B84-$C$5)+$J$4*(($B84-$C$5)^2))) -> 1.6351983e-12 | ... BA84: =SQRT($I$4*$J$4-$K$4^2)/PI()*EXP(-($I$4*((BA$33-$C$4)^2)+2*$K$4*(BA$33-$C$4)*($B84-$C$5)+$J$4*(($B84-$C$5)^2))) -> 1.4706587e-15
A88: 2ND COMPONENT
B90: X | C90: 1 | D90: 2 | E90: 3 | F90: 4 | G90: 5 | H90: 6 | I90: 7 | J90: 8 | K90: 9 | L90: 10 | M90: 11 | N90: 12 | O90: 13 | P90: 14 | Q90: 15 | R90: 16 | S90: 17 | T90: 18 | U90: 19 | V90: 20 | W90: 21 | X90: 22 | Y90: 23 | Z90: 24 | AA90: 25 | AB90: 26 | AC90: 27 | AD90: 28 | AE90: 29 | AF90: 30 | AG90: 31 | AH90: 32 | AI90: 33 | AJ90: 34 | AK90: 35 | AL90: 36 | AM90: 37 | AN90: 38 | AO90: 39 | AP90: 40 | AQ90: 41 | AR90: 42 | AS90: 43 | AT90: 44 | AU90: 45 | AV90: 46 | AW90: 47 | AX90: 48 | AY90: 49 | AZ90: 50 | BA90: 51
A91: Y | C91: =$L$8 -> -3.1588358 | D91: =$C$33+$N$8*(D90-1) -> -2.9646168 | E91: =$C$33+$N$8*(E90-1) -> -2.7703979 | F91: =$C$33+$N$8*(F90-1) -> -2.5761789 | G91: =$C$33+$N$8*(G90-1) -> -2.3819599 | H91: =$C$33+$N$8*(H90-1) -> -2.1877409 | I91: =$C$33+$N$8*(I90-1) -> -1.9935219 | J91: =$C$33+$N$8*(J90-1) -> -1.7993029 | K91: =$C$33+$N$8*(K90-1) -> -1.6050839 | ... BA91: =$C$33+$N$8*(BA90-1) -> 6.5521138
A92: 1 | B92: =$L$9 -> -2.9898586 | C92: =SQRT($I$14*$J$14-$K$14^2)/PI()*EXP(-($I$14*((C$91-$C$14)^2)+2*$K$14*(C$91-$C$14)*($B92-$C$15)+$J$14*(($B92-$C$15)^2))) -> 1.2955599e-30 | D92: =SQRT($I$14*$J$14-$K$14^2)/PI()*EXP(-($I$14*((D$91-$C$14)^2)+2*$K$14*(D$91-$C$14)*($B92-$C$15)+$J$14*(($B92-$C$15)^2))) -> 6.6064284e-30 | E92: =SQRT($I$14*$J$14-$K$14^2)/PI()*EXP(-($I$14*((E$91-$C$14)^2)+2*$K$14*(E$91-$C$14)*($B92-$C$15)+$J$14*(($B92-$C$15)^2))) -> 3.2329731e-29 | F92: =SQRT($I$14*$J$14-$K$14^2)/PI()*EXP(-($I$14*((F$91-$C$14)^2)+2*$K$14*(F$91-$C$14)*($B92-$C$15)+$J$14*(($B92-$C$15)^2))) -> 1.518321e-28 | G92: =SQRT($I$14*$J$14-$K$14^2)/PI()*EXP(-($I$14*((G$91-$C$14)^2)+2*$K$14*(G$91-$C$14)*($B92-$C$15)+$J$14*(($B92-$C$15)^2))) -> 6.8430738e-28 | H92: =SQRT($I$14*$J$14-$K$14^2)/PI()*EXP(-($I$14*((H$91-$C$14)^2)+2*$K$14*(H$91-$C$14)*($B92-$C$15)+$J$14*(($B92-$C$15)^2))) -> 2.9598179e-27 | I92: =SQRT($I$14*$J$14-$K$14^2)/PI()*EXP(-($I$14*((I$91-$C$14)^2)+2*$K$14*(I$91-$C$14)*($B92-$C$15)+$J$14*(($B92-$C$15)^2))) -> 1.2285842e-26 | J92: =SQRT($I$14*$J$14-$K$14^2)/PI()*EXP(-($I$14*((J$91-$C$14)^2)+2*$K$14*(J$91-$C$14)*($B92-$C$15)+$J$14*(($B92-$C$15)^2))) -> 4.8940789e-26 | ... BA92: =SQRT($I$14*$J$14-$K$14^2)/PI()*EXP(-($I$14*((BA$91-$C$14)^2)+2*$K$14*(BA$91-$C$14)*($B92-$C$15)+$J$14*(($B92-$C$15)^2))) -> 3.9123541e-17
A93: 2 | B93: =$B$34+$N$9*(A93-1) -> -2.7986719 | C93: =SQRT($I$14*$J$14-$K$14^2)/PI()*EXP(-($I$14*((C$91-$C$14)^2)+2*$K$14*(C$91-$C$14)*($B93-$C$15)+$J$14*(($B93-$C$15)^2))) -> 1.0154924e-29 | D93: =SQRT($I$14*$J$14-$K$14^2)/PI()*EXP(-($I$14*((D$91-$C$14)^2)+2*$K$14*(D$91-$C$14)*($B93-$C$15)+$J$14*(($B93-$C$15)^2))) -> 5.1494218e-29 | E93: =SQRT($I$14*$J$14-$K$14^2)/PI()*EXP(-($I$14*((E$91-$C$14)^2)+2*$K$14*(E$91-$C$14)*($B93-$C$15)+$J$14*(($B93-$C$15)^2))) -> 2.5059153e-28 | F93: =SQRT($I$14*$J$14-$K$14^2)/PI()*EXP(-($I$14*((F$91-$C$14)^2)+2*$K$14*(F$91-$C$14)*($B93-$C$15)+$J$14*(($B93-$C$15)^2))) -> 1.1703088e-27 | G93: =SQRT($I$14*$J$14-$K$14^2)/PI()*EXP(-($I$14*((G$91-$C$14)^2)+2*$K$14*(G$91-$C$14)*($B93-$C$15)+$J$14*(($B93-$C$15)^2))) -> 5.2451832e-27 | H93: =SQRT($I$14*$J$14-$K$14^2)/PI()*EXP(-($I$14*((H$91-$C$14)^2)+2*$K$14*(H$91-$C$14)*($B93-$C$15)+$J$14*(($B93-$C$15)^2))) -> 2.2560411e-26 | I93: =SQRT($I$14*$J$14-$K$14^2)/PI()*EXP(-($I$14*((I$91-$C$14)^2)+2*$K$14*(I$91-$C$14)*($B93-$C$15)+$J$14*(($B93-$C$15)^2))) -> 9.312354e-26 | J93: =SQRT($I$14*$J$14-$K$14^2)/PI()*EXP(-($I$14*((J$91-$C$14)^2)+2*$K$14*(J$91-$C$14)*($B93-$C$15)+$J$14*(($B93-$C$15)^2))) -> 3.6889103e-25 | ... BA93: =SQRT($I$14*$J$14-$K$14^2)/PI()*EXP(-($I$14*((BA$91-$C$14)^2)+2*$K$14*(BA$91-$C$14)*($B93-$C$15)+$J$14*(($B93-$C$15)^2))) -> 2.3189194e-16
A94: 3 | B94: =$B$34+$N$9*(A94-1) -> -2.6074852 | C94: =SQRT($I$14*$J$14-$K$14^2)/PI()*EXP(-($I$14*((C$91-$C$14)^2)+2*$K$14*(C$91-$C$14)*($B94-$C$15)+$J$14*(($B94-$C$15)^2))) -> 7.5602342e-29 | D94: =SQRT($I$14*$J$14-$K$14^2)/PI()*EXP(-($I$14*((D$91-$C$14)^2)+2*$K$14*(D$91-$C$14)*($B94-$C$15)+$J$14*(($B94-$C$15)^2))) -> 3.8123222e-28 | E94: =SQRT($I$14*$J$14-$K$14^2)/PI()*EXP(-($I$14*((E$91-$C$14)^2)+2*$K$14*(E$91-$C$14)*($B94-$C$15)+$J$14*(($B94-$C$15)^2))) -> 1.8448884e-27 | F94: =SQRT($I$14*$J$14-$K$14^2)/PI()*EXP(-($I$14*((F$91-$C$14)^2)+2*$K$14*(F$91-$C$14)*($B94-$C$15)+$J$14*(($B94-$C$15)^2))) -> 8.5679461e-27 | G94: =SQRT($I$14*$J$14-$K$14^2)/PI()*EXP(-($I$14*((G$91-$C$14)^2)+2*$K$14*(G$91-$C$14)*($B94-$C$15)+$J$14*(($B94-$C$15)^2))) -> 3.8186468e-26 | H94: =SQRT($I$14*$J$14-$K$14^2)/PI()*EXP(-($I$14*((H$91-$C$14)^2)+2*$K$14*(H$91-$C$14)*($B94-$C$15)+$J$14*(($B94-$C$15)^2))) -> 1.6333092e-25 | I94: =SQRT($I$14*$J$14-$K$14^2)/PI()*EXP(-($I$14*((I$91-$C$14)^2)+2*$K$14*(I$91-$C$14)*($B94-$C$15)+$J$14*(($B94-$C$15)^2))) -> 6.7043001e-25 | J94: =SQRT($I$14*$J$14-$K$14^2)/PI()*EXP(-($I$14*((J$91-$C$14)^2)+2*$K$14*(J$91-$C$14)*($B94-$C$15)+$J$14*(($B94-$C$15)^2))) -> 2.6409771e-24 | ... BA94: =SQRT($I$14*$J$14-$K$14^2)/PI()*EXP(-($I$14*((BA$91-$C$14)^2)+2*$K$14*(BA$91-$C$14)*($B94-$C$15)+$J$14*(($B94-$C$15)^2))) -> 1.305487e-15
A95: 4 | B95: =$B$34+$N$9*(A95-1) -> -2.4162986 | C95: =SQRT($I$14*$J$14-$K$14^2)/PI()*EXP(-($I$14*((C$91-$C$14)^2)+2*$K$14*(C$91-$C$14)*($B95-$C$15)+$J$14*(($B95-$C$15)^2))) -> 5.3460525e-28 | D95: =SQRT($I$14*$J$14-$K$14^2)/PI()*EXP(-($I$14*((D$91-$C$14)^2)+2*$K$14*(D$91-$C$14)*($B95-$C$15)+$J$14*(($B95-$C$15)^2))) -> 2.6807736e-27 | E95: =SQRT($I$14*$J$14-$K$14^2)/PI()*EXP(-($I$14*((E$91-$C$14)^2)+2*$K$14*(E$91-$C$14)*($B95-$C$15)+$J$14*(($B95-$C$15)^2))) -> 1.2900698e-26 | F95: =SQRT($I$14*$J$14-$K$14^2)/PI()*EXP(-($I$14*((F$91-$C$14)^2)+2*$K$14*(F$91-$C$14)*($B95-$C$15)+$J$14*(($B95-$C$15)^2))) -> 5.9578888e-26 | G95: =SQRT($I$14*$J$14-$K$14^2)/PI()*EXP(-($I$14*((G$91-$C$14)^2)+2*$K$14*(G$91-$C$14)*($B95-$C$15)+$J$14*(($B95-$C$15)^2))) -> 2.6405702e-25 | H95: =SQRT($I$14*$J$14-$K$14^2)/PI()*EXP(-($I$14*((H$91-$C$14)^2)+2*$K$14*(H$91-$C$14)*($B95-$C$15)+$J$14*(($B95-$C$15)^2))) -> 1.1231279e-24 | I95: =SQRT($I$14*$J$14-$K$14^2)/PI()*EXP(-($I$14*((I$91-$C$14)^2)+2*$K$14*(I$91-$C$14)*($B95-$C$15)+$J$14*(($B95-$C$15)^2))) -> 4.5844455e-24 | J95: =SQRT($I$14*$J$14-$K$14^2)/PI()*EXP(-($I$14*((J$91-$C$14)^2)+2*$K$14*(J$91-$C$14)*($B95-$C$15)+$J$14*(($B95-$C$15)^2))) -> 1.7958521e-23 | ... BA95: =SQRT($I$14*$J$14-$K$14^2)/PI()*EXP(-($I$14*((BA$91-$C$14)^2)+2*$K$14*(BA$91-$C$14)*($B95-$C$15)+$J$14*(($B95-$C$15)^2))) -> 6.9806976e-15
A96: 5 | B96: =$B$34+$N$9*(A96-1) -> -2.2251119 | C96: =SQRT($I$14*$J$14-$K$14^2)/PI()*EXP(-($I$14*((C$91-$C$14)^2)+2*$K$14*(C$91-$C$14)*($B96-$C$15)+$J$14*(($B96-$C$15)^2))) -> 3.5906294e-27 | D96: =SQRT($I$14*$J$14-$K$14^2)/PI()*EXP(-($I$14*((D$91-$C$14)^2)+2*$K$14*(D$91-$C$14)*($B96-$C$15)+$J$14*(($B96-$C$15)^2))) -> 1.7904824e-26 | E96: =SQRT($I$14*$J$14-$K$14^2)/PI()*EXP(-($I$14*((E$91-$C$14)^2)+2*$K$14*(E$91-$C$14)*($B96-$C$15)+$J$14*(($B96-$C$15)^2))) -> 8.5683203e-26 | F96: =SQRT($I$14*$J$14-$K$14^2)/PI()*EXP(-($I$14*((F$91-$C$14)^2)+2*$K$14*(F$91-$C$14)*($B96-$C$15)+$J$14*(($B96-$C$15)^2))) -> 3.9350246e-25 | G96: =SQRT($I$14*$J$14-$K$14^2)/PI()*EXP(-($I$14*((G$91-$C$14)^2)+2*$K$14*(G$91-$C$14)*($B96-$C$15)+$J$14*(($B96-$C$15)^2))) -> 1.7343045e-24 | H96: =SQRT($I$14*$J$14-$K$14^2)/PI()*EXP(-($I$14*((H$91-$C$14)^2)+2*$K$14*(H$91-$C$14)*($B96-$C$15)+$J$14*(($B96-$C$15)^2))) -> 7.3354945e-24 | I96: =SQRT($I$14*$J$14-$K$14^2)/PI()*EXP(-($I$14*((I$91-$C$14)^2)+2*$K$14*(I$91-$C$14)*($B96-$C$15)+$J$14*(($B96-$C$15)^2))) -> 2.9775535e-23 | J96: =SQRT($I$14*$J$14-$K$14^2)/PI()*EXP(-($I$14*((J$91-$C$14)^2)+2*$K$14*(J$91-$C$14)*($B96-$C$15)+$J$14*(($B96-$C$15)^2))) -> 1.1598876e-22 | ... BA96: =SQRT($I$14*$J$14-$K$14^2)/PI()*EXP(-($I$14*((BA$91-$C$14)^2)+2*$K$14*(BA$91-$C$14)*($B96-$C$15)+$J$14*(($B96-$C$15)^2))) -> 3.5453941e-14
A97: 6 | B97: =$B$34+$N$9*(A97-1) -> -2.0339252 | C97: =SQRT($I$14*$J$14-$K$14^2)/PI()*EXP(-($I$14*((C$91-$C$14)^2)+2*$K$14*(C$91-$C$14)*($B97-$C$15)+$J$14*(($B97-$C$15)^2))) -> 2.2905899e-26 | D97: =SQRT($I$14*$J$14-$K$14^2)/PI()*EXP(-($I$14*((D$91-$C$14)^2)+2*$K$14*(D$91-$C$14)*($B97-$C$15)+$J$14*(($B97-$C$15)^2))) -> 1.1358459e-25 | E97: =SQRT($I$14*$J$14-$K$14^2)/PI()*EXP(-($I$14*((E$91-$C$14)^2)+2*$K$14*(E$91-$C$14)*($B97-$C$15)+$J$14*(($B97-$C$15)^2))) -> 5.4052725e-25 | F97: =SQRT($I$14*$J$14-$K$14^2)/PI()*EXP(-($I$14*((F$91-$C$14)^2)+2*$K$14*(F$91-$C$14)*($B97-$C$15)+$J$14*(($B97-$C$15)^2))) -> 2.46855e-24 | G97: =SQRT($I$14*$J$14-$K$14^2)/PI()*EXP(-($I$14*((G$91-$C$14)^2)+2*$K$14*(G$91-$C$14)*($B97-$C$15)+$J$14*(($B97-$C$15)^2))) -> 1.0819131e-23 | H97: =SQRT($I$14*$J$14-$K$14^2)/PI()*EXP(-($I$14*((H$91-$C$14)^2)+2*$K$14*(H$91-$C$14)*($B97-$C$15)+$J$14*(($B97-$C$15)^2))) -> 4.5506035e-23 | I97: =SQRT($I$14*$J$14-$K$14^2)/PI()*EXP(-($I$14*((I$91-$C$14)^2)+2*$K$14*(I$91-$C$14)*($B97-$C$15)+$J$14*(($B97-$C$15)^2))) -> 1.8368417e-22 | J97: =SQRT($I$14*$J$14-$K$14^2)/PI()*EXP(-($I$14*((J$91-$C$14)^2)+2*$K$14*(J$91-$C$14)*($B97-$C$15)+$J$14*(($B97-$C$15)^2))) -> 7.1154213e-22 | ... BA97: =SQRT($I$14*$J$14-$K$14^2)/PI()*EXP(-($I$14*((BA$91-$C$14)^2)+2*$K$14*(BA$91-$C$14)*($B97-$C$15)+$J$14*(($B97-$C$15)^2))) -> 1.7102894e-13
...

Sheet Simulated data with conf. reg.
D1: 1st component | G1: Pi_1 | H1: 0.6
D3: Mean | E3: Variance | F3: Covariance | G3: Std. Derivation
C4: X | D4: 0 | E4: 2 | F4: -0.5 | G4: =SQRT(E4) -> 1.4142136
C5: Y | D5: 0 | E5: 1 | G5: =SQRT(E5) -> 1
D7: Det | E7: =E4*E5-F4^2 -> 1.75
D8: Corr | E8: =F4/(G4*G5) -> -0.35355339
D10: 2nd component | G10: Pi_2 | H10: =1-H1 -> 0.4
D12: Mean | E12: Variance | F12: Covariance | G12: Std. Derivation
C13: X | D13: 4 | E13: 1 | F13: 0.6 | G13: =SQRT(E13) -> 1
C14: Y | D14: 4 | E14: 2 | G14: =SQRT(E14) -> 1.4142136
B17: Mức ý nghĩa alpha: | D17: 0.05

Sheet Simulation data
D1: 1st component | G1: Pi_1 | H1: ='Simulated data with conf. reg.'!H1 -> 0.6
D3: Mean | E3: Variance | F3: Covariance | G3: Std. Derivation | J3: c11 | K3: c22 | L3: c12 | P3: =2*J4 -> 0.57142857 | Q3: =2*L4 -> 0.28571429 | S3: a11 | T3: a12
C4: X | D4: ='Simulated data with conf. reg.'!D4 -> 0 | E4: ='Simulated data with conf. reg.'!E4 -> 2 | F4: ='Simulated data with conf. reg.'!F4 -> -0.5 | G4: =SQRT(E4) -> 1.4142136 | J4: =(E5/E7)/2 -> 0.28571429 | K4: =(E4/E7)/2 -> 0.57142857 | L4: =-(F4/E7)/2 -> 0.14285714 | N4: Sigma_1^(-1) | P4: =2*L4 -> 0.28571429 | Q4: =2*K4 -> 1.1428571 | S4: a12 | T4: a22
C5: Y | D5: ='Simulated data with conf. reg.'!D5 -> 0 | E5: ='Simulated data with conf. reg.'!E5 -> 1 | G5: =SQRT(E5) -> 1
D7: Det | E7: =E4*E5-F4^2 -> 1.75
D8: Corr | E8: =F4/(G4*G5) -> -0.35355339
N9: =1/(P13*Q14-Q13^2) -> 1.64
D11: 2nd component | G11: Pi_2 | H11: =1-H1 -> 0.4
D13: Mean | E13: Variance | F13: Covariance | G13: Std. Derivation | J13: d11 | K13: d22 | L13: d12 | P13: =2*J14 -> 1.2195122 | Q13: =2*L14 -> -0.36585366 | S13: b11 | T13: b12
C14: X | D14: ='Simulated data with conf. reg.'!D13 -> 4 | E14: ='Simulated data with conf. reg.'!E13 -> 1 | F14: ='Simulated data with conf. reg.'!F13 -> 0.6 | G14: =SQRT(E14) -> 1 | J14: =(E15/E17)/2 -> 0.6097561 | K14: =(E14/E17)/2 -> 0.30487805 | L14: =-(F14/E17)/2 -> -0.18292683 | N14: Sigma_2^(-1) | P14: =2*L14 -> -0.36585366 | Q14: =2*K14 -> 0.6097561 | S14: b12 | T14: b22
C15: Y | D15: ='Simulated data with conf. reg.'!D14 -> 4 | E15: ='Simulated data with conf. reg.'!E14 -> 2 | G15: =SQRT(E15) -> 1.4142136
J16: Mức ý nghĩa alpha: | L16: ='Simulated data with conf. reg.'!D17 -> 0.05
D17: Det | E17: =E14*E15-F14^2 -> 1.64 | N17: A1 | O17: =(P3*Q4-P4^2)/Q4 -> 0.5 | Q17: A2 | R17: =(P13*Q14-P14^2)/Q14 -> 1
D18: Corr | E18: =F14/(G14*G15) -> 0.42426407 | N18: B1 | O18: =Q4 -> 1.1428571 | Q18: B2 | R18: =Q14 -> 0.6097561
N19: C_alpha | O19: =_xlfn.CHISQ.INV.RT(L16,2) -> 5.9914645 | Q19: C_alpha | R19: =_xlfn.CHISQ.INV.RT(L16,2) -> 5.9914645
A20: STT | B20: Rand | C20: X | D20: Y | E20: Z | F20: Class 1 | G20: Class 2 | H20: Ellipsoid.1a | I20: Ellipsoid.1b | J20: Ellipsoid.2a | K20: Ellipsoid.2b
A21: 1 | B21: =RAND() -> 0.19104939 | C21: =IF(E21=1,_xlfn.NORM.INV(RAND(),$D$4,$G$4),_xlfn.NORM.INV(RAND(),$D$14,$G$14)) -> -2.145809 | D21: =IF(E21=1,_xlfn.NORM.INV(RAND(),$D$5-$L$4/$K$4*(C21-$D$4),SQRT(1/(2*$K$4))),_xlfn.NORM.INV(RAND(),$D$15-$L$14/$K$14*(C21-$D$14),SQRT(1/(2*$K$14)))) -> 0.97043817 | E21: =IF(B21<$H$1,1,2) -> 1 | F21: =IF($E21=1,D21,NA()) -> 0.97043817 | G21: =IF($E21=2,D21,NA()) -> #N/A | H21: =NA() -> #N/A | I21: =NA() -> #N/A | J21: =NA() -> #N/A | K21: =NA() -> #N/A | N21: Range1 | O21: =2*SQRT(O19/O17) -> 6.9232735 | Q21: Range2 | R21: =2*SQRT(R19/R17) -> 4.8954937
A22: 2 | B22: =RAND() -> 0.89121216 | C22: =IF(E22=1,_xlfn.NORM.INV(RAND(),$D$4,$G$4),_xlfn.NORM.INV(RAND(),$D$14,$G$14)) -> 3.232136 | D22: =IF(E22=1,_xlfn.NORM.INV(RAND(),$D$5-$L$4/$K$4*(C22-$D$4),SQRT(1/(2*$K$4))),_xlfn.NORM.INV(RAND(),$D$15-$L$14/$K$14*(C22-$D$14),SQRT(1/(2*$K$14)))) -> 3.2142563 | E22: =IF(B22<$H$1,1,2) -> 2 | F22: =IF($E22=1,D22,NA()) -> #N/A | G22: =IF($E22=2,D22,NA()) -> 3.2142563 | H22: =NA() -> #N/A | I22: =NA() -> #N/A | J22: =NA() -> #N/A | K22: =NA() -> #N/A
A23: 3 | B23: =RAND() -> 0.83943672 | C23: =IF(E23=1,_xlfn.NORM.INV(RAND(),$D$4,$G$4),_xlfn.NORM.INV(RAND(),$D$14,$G$14)) -> 4.9401719 | D23: =IF(E23=1,_xlfn.NORM.INV(RAND(),$D$5-$L$4/$K$4*(C23-$D$4),SQRT(1/(2*$K$4))),_xlfn.NORM.INV(RAND(),$D$15-$L$14/$K$14*(C23-$D$14),SQRT(1/(2*$K$14)))) -> 3.8684483 | E23: =IF(B23<$H$1,1,2) -> 2 | F23: =IF($E23=1,D23,NA()) -> #N/A | G23: =IF($E23=2,D23,NA()) -> 3.8684483 | H23: =NA() -> #N/A | I23: =NA() -> #N/A | J23: =NA() -> #N/A | K23: =NA() -> #N/A | N23: Ellipsoid.1 | R23: Ellipsoid.2
A24: 4 | B24: =RAND() -> 0.70004635 | C24: =IF(E24=1,_xlfn.NORM.INV(RAND(),$D$4,$G$4),_xlfn.NORM.INV(RAND(),$D$14,$G$14)) -> 3.8101809 | D24: =IF(E24=1,_xlfn.NORM.INV(RAND(),$D$5-$L$4/$K$4*(C24-$D$4),SQRT(1/(2*$K$4))),_xlfn.NORM.INV(RAND(),$D$15-$L$14/$K$14*(C24-$D$14),SQRT(1/(2*$K$14)))) -> 1.2921022 | E24: =IF(B24<$H$1,1,2) -> 2 | F24: =IF($E24=1,D24,NA()) -> #N/A | G24: =IF($E24=2,D24,NA()) -> 1.2921022 | H24: =NA() -> #N/A | I24: =NA() -> #N/A | J24: =NA() -> #N/A | K24: =NA() -> #N/A | M24: STT | N24: X1 | O24: Y1 | P24: -Y1 | R24: X2 | S24: Y2 | T24: -Y2
A25: 5 | B25: =RAND() -> 0.14322943 | C25: =IF(E25=1,_xlfn.NORM.INV(RAND(),$D$4,$G$4),_xlfn.NORM.INV(RAND(),$D$14,$G$14)) -> -0.049145426 | D25: =IF(E25=1,_xlfn.NORM.INV(RAND(),$D$5-$L$4/$K$4*(C25-$D$4),SQRT(1/(2*$K$4))),_xlfn.NORM.INV(RAND(),$D$15-$L$14/$K$14*(C25-$D$14),SQRT(1/(2*$K$14)))) -> 0.13385796 | E25: =IF(B25<$H$1,1,2) -> 1 | F25: =IF($E25=1,D25,NA()) -> 0.13385796 | G25: =IF($E25=2,D25,NA()) -> #N/A | H25: =NA() -> #N/A | I25: =NA() -> #N/A | J25: =NA() -> #N/A | K25: =NA() -> #N/A | M25: 0 | N25: =-O21/2 -> -3.4616368 | O25: =SQRT(ABS($O$19-$O$17*$N25^2)/$O$18)-$Q$3/$Q$4*$N25 -> 0.86540922 | P25: =-SQRT(ABS($O$19-$O$17*$N25^2)/$O$18)-$Q$3/$Q$4*$N25 -> 0.86540916 | R25: =-R21/2 -> -2.4477468 | S25: =SQRT(ABS($R$19-$R$17*$R25^2)/$R$18)-$Q$13/$Q$14*$R25 -> -1.4686481 | T25: =-SQRT(ABS($R$19-$R$17*$R25^2)/$R$18)-$Q$13/$Q$14*$R25 -> -1.4686481
A26: 6 | B26: =RAND() -> 0.049881561 | C26: =IF(E26=1,_xlfn.NORM.INV(RAND(),$D$4,$G$4),_xlfn.NORM.INV(RAND(),$D$14,$G$14)) -> -0.025228433 | D26: =IF(E26=1,_xlfn.NORM.INV(RAND(),$D$5-$L$4/$K$4*(C26-$D$4),SQRT(1/(2*$K$4))),_xlfn.NORM.INV(RAND(),$D$15-$L$14/$K$14*(C26-$D$14),SQRT(1/(2*$K$14)))) -> 1.593934 | E26: =IF(B26<$H$1,1,2) -> 1 | F26: =IF($E26=1,D26,NA()) -> 1.593934 | G26: =IF($E26=2,D26,NA()) -> #N/A | H26: =NA() -> #N/A | I26: =NA() -> #N/A | J26: =NA() -> #N/A | K26: =NA() -> #N/A | M26: 1 | N26: =$N$25+M26*$O$21/50 -> -3.3231713 | O26: =SQRT(ABS($O$19-$O$17*$N26^2)/$O$18)-$Q$3/$Q$4*$N26 -> 1.4718969 | P26: =-SQRT(ABS($O$19-$O$17*$N26^2)/$O$18)-$Q$3/$Q$4*$N26 -> 0.18968872 | R26: =$R$25+M26*$R$21/50 -> -2.349837 | S26: =SQRT(ABS($R$19-$R$17*$R26^2)/$R$18)-$Q$13/$Q$14*$R26 -> -0.53220146 | T26: =-SQRT(ABS($R$19-$R$17*$R26^2)/$R$18)-$Q$13/$Q$14*$R26 -> -2.2876029
A27: 7 | B27: =RAND() -> 0.43046026 | C27: =IF(E27=1,_xlfn.NORM.INV(RAND(),$D$4,$G$4),_xlfn.NORM.INV(RAND(),$D$14,$G$14)) -> -0.29220079 | D27: =IF(E27=1,_xlfn.NORM.INV(RAND(),$D$5-$L$4/$K$4*(C27-$D$4),SQRT(1/(2*$K$4))),_xlfn.NORM.INV(RAND(),$D$15-$L$14/$K$14*(C27-$D$14),SQRT(1/(2*$K$14)))) -> -0.2861831 | E27: =IF(B27<$H$1,1,2) -> 1 | F27: =IF($E27=1,D27,NA()) -> -0.2861831 | G27: =IF($E27=2,D27,NA()) -> #N/A | H27: =NA() -> #N/A | I27: =NA() -> #N/A | J27: =NA() -> #N/A | K27: =NA() -> #N/A | M27: 2 | N27: =$N$25+M27*$O$21/50 -> -3.1847058 | O27: =SQRT(ABS($O$19-$O$17*$N27^2)/$O$18)-$Q$3/$Q$4*$N27 -> 1.6935353 | P27: =-SQRT(ABS($O$19-$O$17*$N27^2)/$O$18)-$Q$3/$Q$4*$N27 -> -0.10118235 | R27: =$R$25+M27*$R$21/50 -> -2.2519271 | S27: =SQRT(ABS($R$19-$R$17*$R27^2)/$R$18)-$Q$13/$Q$14*$R27 -> -0.12263117 | T27: =-SQRT(ABS($R$19-$R$17*$R27^2)/$R$18)-$Q$13/$Q$14*$R27 -> -2.5796813
A28: 8 | B28: =RAND() -> 0.40180185 | C28: =IF(E28=1,_xlfn.NORM.INV(RAND(),$D$4,$G$4),_xlfn.NORM.INV(RAND(),$D$14,$G$14)) -> 0.49613641 | D28: =IF(E28=1,_xlfn.NORM.INV(RAND(),$D$5-$L$4/$K$4*(C28-$D$4),SQRT(1/(2*$K$4))),_xlfn.NORM.INV(RAND(),$D$15-$L$14/$K$14*(C28-$D$14),SQRT(1/(2*$K$14)))) -> -0.76989466 | E28: =IF(B28<$H$1,1,2) -> 1 | F28: =IF($E28=1,D28,NA()) -> -0.76989466 | G28: =IF($E28=2,D28,NA()) -> #N/A | H28: =NA() -> #N/A | I28: =NA() -> #N/A | J28: =NA() -> #N/A | K28: =NA() -> #N/A | M28: 3 | N28: =$N$25+M28*$O$21/50 -> -3.0462404 | O28: =SQRT(ABS($O$19-$O$17*$N28^2)/$O$18)-$Q$3/$Q$4*$N28 -> 1.8490871 | P28: =-SQRT(ABS($O$19-$O$17*$N28^2)/$O$18)-$Q$3/$Q$4*$N28 -> -0.32596697 | R28: =$R$25+M28*$R$21/50 -> -2.1540172 | S28: =SQRT(ABS($R$19-$R$17*$R28^2)/$R$18)-$Q$13/$Q$14*$R28 -> 0.19646375 | T28: =-SQRT(ABS($R$19-$R$17*$R28^2)/$R$18)-$Q$13/$Q$14*$R28 -> -2.7812844
A29: 9 | B29: =RAND() -> 0.49368768 | C29: =IF(E29=1,_xlfn.NORM.INV(RAND(),$D$4,$G$4),_xlfn.NORM.INV(RAND(),$D$14,$G$14)) -> -0.56473713 | D29: =IF(E29=1,_xlfn.NORM.INV(RAND(),$D$5-$L$4/$K$4*(C29-$D$4),SQRT(1/(2*$K$4))),_xlfn.NORM.INV(RAND(),$D$15-$L$14/$K$14*(C29-$D$14),SQRT(1/(2*$K$14)))) -> -0.53080306 | E29: =IF(B29<$H$1,1,2) -> 1 | F29: =IF($E29=1,D29,NA()) -> -0.53080306 | G29: =IF($E29=2,D29,NA()) -> #N/A | H29: =NA() -> #N/A | I29: =NA() -> #N/A | J29: =NA() -> #N/A | K29: =NA() -> #N/A | M29: 4 | N29: =$N$25+M29*$O$21/50 -> -2.9077749 | O29: =SQRT(ABS($O$19-$O$17*$N29^2)/$O$18)-$Q$3/$Q$4*$N29 -> 1.9692807 | P29: =-SQRT(ABS($O$19-$O$17*$N29^2)/$O$18)-$Q$3/$Q$4*$N29 -> -0.5153933 | R29: =$R$25+M29*$R$21/50 -> -2.0561073 | S29: =SQRT(ABS($R$19-$R$17*$R29^2)/$R$18)-$Q$13/$Q$14*$R29 -> 0.46715156 | T29: =-SQRT(ABS($R$19-$R$17*$R29^2)/$R$18)-$Q$13/$Q$14*$R29 -> -2.9344804
A30: 10 | B30: =RAND() -> 0.70583949 | C30: =IF(E30=1,_xlfn.NORM.INV(RAND(),$D$4,$G$4),_xlfn.NORM.INV(RAND(),$D$14,$G$14)) -> 4.2390781 | D30: =IF(E30=1,_xlfn.NORM.INV(RAND(),$D$5-$L$4/$K$4*(C30-$D$4),SQRT(1/(2*$K$4))),_xlfn.NORM.INV(RAND(),$D$15-$L$14/$K$14*(C30-$D$14),SQRT(1/(2*$K$14)))) -> 3.1028548 | E30: =IF(B30<$H$1,1,2) -> 2 | F30: =IF($E30=1,D30,NA()) -> #N/A | G30: =IF($E30=2,D30,NA()) -> 3.1028548 | H30: =NA() -> #N/A | I30: =NA() -> #N/A | J30: =NA() -> #N/A | K30: =NA() -> #N/A | M30: 5 | N30: =$N$25+M30*$O$21/50 -> -2.7693094 | O30: =SQRT(ABS($O$19-$O$17*$N30^2)/$O$18)-$Q$3/$Q$4*$N30 -> 2.0661219 | P30: =-SQRT(ABS($O$19-$O$17*$N30^2)/$O$18)-$Q$3/$Q$4*$N30 -> -0.68146715 | R30: =$R$25+M30*$R$21/50 -> -1.9581975 | S30: =SQRT(ABS($R$19-$R$17*$R30^2)/$R$18)-$Q$13/$Q$14*$R30 -> 0.70586877 | T30: =-SQRT(ABS($R$19-$R$17*$R30^2)/$R$18)-$Q$13/$Q$14*$R30 -> -3.0557057
A31: 11 | B31: =RAND() -> 0.47812707 | C31: =IF(E31=1,_xlfn.NORM.INV(RAND(),$D$4,$G$4),_xlfn.NORM.INV(RAND(),$D$14,$G$14)) -> -1.1607912 | D31: =IF(E31=1,_xlfn.NORM.INV(RAND(),$D$5-$L$4/$K$4*(C31-$D$4),SQRT(1/(2*$K$4))),_xlfn.NORM.INV(RAND(),$D$15-$L$14/$K$14*(C31-$D$14),SQRT(1/(2*$K$14)))) -> -0.096999823 | E31: =IF(B31<$H$1,1,2) -> 1 | F31: =IF($E31=1,D31,NA()) -> -0.096999823 | G31: =IF($E31=2,D31,NA()) -> #N/A | H31: =NA() -> #N/A | I31: =NA() -> #N/A | J31: =NA() -> #N/A | K31: =NA() -> #N/A | M31: 6 | N31: =$N$25+M31*$O$21/50 -> -2.6308439 | O31: =SQRT(ABS($O$19-$O$17*$N31^2)/$O$18)-$Q$3/$Q$4*$N31 -> 2.1458122 | P31: =-SQRT(ABS($O$19-$O$17*$N31^2)/$O$18)-$Q$3/$Q$4*$N31 -> -0.83039025 | R31: =$R$25+M31*$R$21/50 -> -1.8602876 | S31: =SQRT(ABS($R$19-$R$17*$R31^2)/$R$18)-$Q$13/$Q$14*$R31 -> 0.92110582 | T31: =-SQRT(ABS($R$19-$R$17*$R31^2)/$R$18)-$Q$13/$Q$14*$R31 -> -3.1534509
A32: 12 | B32: =RAND() -> 0.9104919 | C32: =IF(E32=1,_xlfn.NORM.INV(RAND(),$D$4,$G$4),_xlfn.NORM.INV(RAND(),$D$14,$G$14)) -> 4.3915783 | D32: =IF(E32=1,_xlfn.NORM.INV(RAND(),$D$5-$L$4/$K$4*(C32-$D$4),SQRT(1/(2*$K$4))),_xlfn.NORM.INV(RAND(),$D$15-$L$14/$K$14*(C32-$D$14),SQRT(1/(2*$K$14)))) -> 4.7485269 | E32: =IF(B32<$H$1,1,2) -> 2 | F32: =IF($E32=1,D32,NA()) -> #N/A | G32: =IF($E32=2,D32,NA()) -> 4.7485269 | H32: =NA() -> #N/A | I32: =NA() -> #N/A | J32: =NA() -> #N/A | K32: =NA() -> #N/A | M32: 7 | N32: =$N$25+M32*$O$21/50 -> -2.4923785 | O32: =SQRT(ABS($O$19-$O$17*$N32^2)/$O$18)-$Q$3/$Q$4*$N32 -> 2.2120575 | P32: =-SQRT(ABS($O$19-$O$17*$N32^2)/$O$18)-$Q$3/$Q$4*$N32 -> -0.9658683 | R32: =$R$25+M32*$R$21/50 -> -1.7623777 | S32: =SQRT(ABS($R$19-$R$17*$R32^2)/$R$18)-$Q$13/$Q$14*$R32 -> 1.117936 | T32: =-SQRT(ABS($R$19-$R$17*$R32^2)/$R$18)-$Q$13/$Q$14*$R32 -> -3.2327892
A33: 13 | B33: =RAND() -> 0.34693275 | C33: =IF(E33=1,_xlfn.NORM.INV(RAND(),$D$4,$G$4),_xlfn.NORM.INV(RAND(),$D$14,$G$14)) -> -1.6970819 | D33: =IF(E33=1,_xlfn.NORM.INV(RAND(),$D$5-$L$4/$K$4*(C33-$D$4),SQRT(1/(2*$K$4))),_xlfn.NORM.INV(RAND(),$D$15-$L$14/$K$14*(C33-$D$14),SQRT(1/(2*$K$14)))) -> 0.62784154 | E33: =IF(B33<$H$1,1,2) -> 1 | F33: =IF($E33=1,D33,NA()) -> 0.62784154 | G33: =IF($E33=2,D33,NA()) -> #N/A | H33: =NA() -> #N/A | I33: =NA() -> #N/A | J33: =NA() -> #N/A | K33: =NA() -> #N/A | M33: 8 | N33: =$N$25+M33*$O$21/50 -> -2.353913 | O33: =SQRT(ABS($O$19-$O$17*$N33^2)/$O$18)-$Q$3/$Q$4*$N33 -> 2.2672829 | P33: =-SQRT(ABS($O$19-$O$17*$N33^2)/$O$18)-$Q$3/$Q$4*$N33 -> -1.0903264 | R33: =$R$25+M33*$R$21/50 -> -1.6644678 | S33: =SQRT(ABS($R$19-$R$17*$R33^2)/$R$18)-$Q$13/$Q$14*$R33 -> 1.2996793 | T33: =-SQRT(ABS($R$19-$R$17*$R33^2)/$R$18)-$Q$13/$Q$14*$R33 -> -3.2970407
A34: 14 | B34: =RAND() -> 0.42667805 | C34: =IF(E34=1,_xlfn.NORM.INV(RAND(),$D$4,$G$4),_xlfn.NORM.INV(RAND(),$D$14,$G$14)) -> -1.1039834 | D34: =IF(E34=1,_xlfn.NORM.INV(RAND(),$D$5-$L$4/$K$4*(C34-$D$4),SQRT(1/(2*$K$4))),_xlfn.NORM.INV(RAND(),$D$15-$L$14/$K$14*(C34-$D$14),SQRT(1/(2*$K$14)))) -> -0.58528186 | E34: =IF(B34<$H$1,1,2) -> 1 | F34: =IF($E34=1,D34,NA()) -> -0.58528186 | G34: =IF($E34=2,D34,NA()) -> #N/A | H34: =NA() -> #N/A | I34: =NA() -> #N/A | J34: =NA() -> #N/A | K34: =NA() -> #N/A | M34: 9 | N34: =$N$25+M34*$O$21/50 -> -2.2154475 | O34: =SQRT(ABS($O$19-$O$17*$N34^2)/$O$18)-$Q$3/$Q$4*$N34 -> 2.3131773 | P34: =-SQRT(ABS($O$19-$O$17*$N34^2)/$O$18)-$Q$3/$Q$4*$N34 -> -1.2054535 | R34: =$R$25+M34*$R$21/50 -> -1.566558 | S34: =SQRT(ABS($R$19-$R$17*$R34^2)/$R$18)-$Q$13/$Q$14*$R34 -> 1.4686481 | T34: =-SQRT(ABS($R$19-$R$17*$R34^2)/$R$18)-$Q$13/$Q$14*$R34 -> -3.3485177
A35: 15 | B35: =RAND() -> 0.60611497 | C35: =IF(E35=1,_xlfn.NORM.INV(RAND(),$D$4,$G$4),_xlfn.NORM.INV(RAND(),$D$14,$G$14)) -> 3.8594641 | D35: =IF(E35=1,_xlfn.NORM.INV(RAND(),$D$5-$L$4/$K$4*(C35-$D$4),SQRT(1/(2*$K$4))),_xlfn.NORM.INV(RAND(),$D$15-$L$14/$K$14*(C35-$D$14),SQRT(1/(2*$K$14)))) -> 5.5760379 | E35: =IF(B35<$H$1,1,2) -> 2 | F35: =IF($E35=1,D35,NA()) -> #N/A | G35: =IF($E35=2,D35,NA()) -> 5.5760379 | H35: =NA() -> #N/A | I35: =NA() -> #N/A | J35: =NA() -> #N/A | K35: =NA() -> #N/A | M35: 10 | N35: =$N$25+M35*$O$21/50 -> -2.0769821 | O35: =SQRT(ABS($O$19-$O$17*$N35^2)/$O$18)-$Q$3/$Q$4*$N35 -> 2.3509715 | P35: =-SQRT(ABS($O$19-$O$17*$N35^2)/$O$18)-$Q$3/$Q$4*$N35 -> -1.3124805 | R35: =$R$25+M35*$R$21/50 -> -1.4686481 | S35: =SQRT(ABS($R$19-$R$17*$R35^2)/$R$18)-$Q$13/$Q$14*$R35 -> 1.6265275 | T35: =-SQRT(ABS($R$19-$R$17*$R35^2)/$R$18)-$Q$13/$Q$14*$R35 -> -3.3889052
A36: 16 | B36: =RAND() -> 0.046387169 | C36: =IF(E36=1,_xlfn.NORM.INV(RAND(),$D$4,$G$4),_xlfn.NORM.INV(RAND(),$D$14,$G$14)) -> -1.5888254 | D36: =IF(E36=1,_xlfn.NORM.INV(RAND(),$D$5-$L$4/$K$4*(C36-$D$4),SQRT(1/(2*$K$4))),_xlfn.NORM.INV(RAND(),$D$15-$L$14/$K$14*(C36-$D$14),SQRT(1/(2*$K$14)))) -> 0.84490333 | E36: =IF(B36<$H$1,1,2) -> 1 | F36: =IF($E36=1,D36,NA()) -> 0.84490333 | G36: =IF($E36=2,D36,NA()) -> #N/A | H36: =NA() -> #N/A | I36: =NA() -> #N/A | J36: =NA() -> #N/A | K36: =NA() -> #N/A | M36: 11 | N36: =$N$25+M36*$O$21/50 -> -1.9385166 | O36: =SQRT(ABS($O$19-$O$17*$N36^2)/$O$18)-$Q$3/$Q$4*$N36 -> 2.3815935 | P36: =-SQRT(ABS($O$19-$O$17*$N36^2)/$O$18)-$Q$3/$Q$4*$N36 -> -1.4123352 | R36: =$R$25+M36*$R$21/50 -> -1.3707382 | S36: =SQRT(ABS($R$19-$R$17*$R36^2)/$R$18)-$Q$13/$Q$14*$R36 -> 1.7745876 | T36: =-SQRT(ABS($R$19-$R$17*$R36^2)/$R$18)-$Q$13/$Q$14*$R36 -> -3.4194735
A37: 17 | B37: =RAND() -> 0.76228729 | C37: =IF(E37=1,_xlfn.NORM.INV(RAND(),$D$4,$G$4),_xlfn.NORM.INV(RAND(),$D$14,$G$14)) -> 3.1700255 | D37: =IF(E37=1,_xlfn.NORM.INV(RAND(),$D$5-$L$4/$K$4*(C37-$D$4),SQRT(1/(2*$K$4))),_xlfn.NORM.INV(RAND(),$D$15-$L$14/$K$14*(C37-$D$14),SQRT(1/(2*$K$14)))) -> 3.1461149 | E37: =IF(B37<$H$1,1,2) -> 2 | F37: =IF($E37=1,D37,NA()) -> #N/A | G37: =IF($E37=2,D37,NA()) -> 3.1461149 | H37: =NA() -> #N/A | I37: =NA() -> #N/A | J37: =NA() -> #N/A | K37: =NA() -> #N/A | M37: 12 | N37: =$N$25+M37*$O$21/50 -> -1.8000511 | O37: =SQRT(ABS($O$19-$O$17*$N37^2)/$O$18)-$Q$3/$Q$4*$N37 -> 2.405761 | P37: =-SQRT(ABS($O$19-$O$17*$N37^2)/$O$18)-$Q$3/$Q$4*$N37 -> -1.5057354 | R37: =$R$25+M37*$R$21/50 -> -1.2728284 | S37: =SQRT(ABS($R$19-$R$17*$R37^2)/$R$18)-$Q$13/$Q$14*$R37 -> 1.9138113 | T37: =-SQRT(ABS($R$19-$R$17*$R37^2)/$R$18)-$Q$13/$Q$14*$R37 -> -3.4412054
... A75: 55 | B75: =RAND() -> 0.53742841 | C75: =IF(E75=1,_xlfn.NORM.INV(RAND(),$D$4,$G$4),_xlfn.NORM.INV(RAND(),$D$14,$G$14)) -> -0.36732403 | D75: =IF(E75=1,_xlfn.NORM.INV(RAND(),$D$5-$L$4/$K$4*(C75-$D$4),SQRT(1/(2*$K$4))),_xlfn.NORM.INV(RAND(),$D$15-$L$14/$K$14*(C75-$D$14),SQRT(1/(2*$K$14)))) -> 0.41289903 | E75: =IF(B75<$H$1,1,2) -> 1 | F75: =IF($E75=1,D75,NA()) -> 0.41289903 | G75: =IF($E75=2,D75,NA()) -> #N/A | H75: =NA() -> #N/A | I75: =NA() -> #N/A | J75: =NA() -> #N/A | K75: =NA() -> #N/A | M75: 50 | N75: =$N$25+M75*$O$21/50 -> 3.4616368 | O75: =SQRT(ABS($O$19-$O$17*$N75^2)/$O$18)-$Q$3/$Q$4*$N75 -> -0.86540914 | P75: =-SQRT(ABS($O$19-$O$17*$N75^2)/$O$18)-$Q$3/$Q$4*$N75 -> -0.86540925 | R75: =$R$25+M75*$R$21/50 -> 2.4477468 | S75: =SQRT(ABS($R$19-$R$17*$R75^2)/$R$18)-$Q$13/$Q$14*$R75 -> 1.4686481 | T75: =-SQRT(ABS($R$19-$R$17*$R75^2)/$R$18)-$Q$13/$Q$14*$R75 -> 1.4686481
A76: 56 | B76: =RAND() -> 0.29322298 | C76: =IF(E76=1,_xlfn.NORM.INV(RAND(),$D$4,$G$4),_xlfn.NORM.INV(RAND(),$D$14,$G$14)) -> 0.44572589 | D76: =IF(E76=1,_xlfn.NORM.INV(RAND(),$D$5-$L$4/$K$4*(C76-$D$4),SQRT(1/(2*$K$4))),_xlfn.NORM.INV(RAND(),$D$15-$L$14/$K$14*(C76-$D$14),SQRT(1/(2*$K$14)))) -> 0.089232961 | E76: =IF(B76<$H$1,1,2) -> 1 | F76: =IF($E76=1,D76,NA()) -> 0.089232961 | G76: =IF($E76=2,D76,NA()) -> #N/A | H76: =NA() -> #N/A | I76: =NA() -> #N/A | J76: =NA() -> #N/A | K76: =NA() -> #N/A
A77: 57 | B77: =RAND() -> 0.40685649 | C77: =IF(E77=1,_xlfn.NORM.INV(RAND(),$D$4,$G$4),_xlfn.NORM.INV(RAND(),$D$14,$G$14)) -> -0.55964932 | D77: =IF(E77=1,_xlfn.NORM.INV(RAND(),$D$5-$L$4/$K$4*(C77-$D$4),SQRT(1/(2*$K$4))),_xlfn.NORM.INV(RAND(),$D$15-$L$14/$K$14*(C77-$D$14),SQRT(1/(2*$K$14)))) -> -0.99111348 | E77: =IF(B77<$H$1,1,2) -> 1 | F77: =IF($E77=1,D77,NA()) -> -0.99111348 | G77: =IF($E77=2,D77,NA()) -> #N/A | H77: =NA() -> #N/A | I77: =NA() -> #N/A | J77: =NA() -> #N/A | K77: =NA() -> #N/A
A78: 58 | B78: =RAND() -> 0.10138494 | C78: =IF(E78=1,_xlfn.NORM.INV(RAND(),$D$4,$G$4),_xlfn.NORM.INV(RAND(),$D$14,$G$14)) -> -1.0201682 | D78: =IF(E78=1,_xlfn.NORM.INV(RAND(),$D$5-$L$4/$K$4*(C78-$D$4),SQRT(1/(2*$K$4))),_xlfn.NORM.INV(RAND(),$D$15-$L$14/$K$14*(C78-$D$14),SQRT(1/(2*$K$14)))) -> 0.44684114 | E78: =IF(B78<$H$1,1,2) -> 1 | F78: =IF($E78=1,D78,NA()) -> 0.44684114 | G78: =IF($E78=2,D78,NA()) -> #N/A | H78: =NA() -> #N/A | I78: =NA() -> #N/A | J78: =NA() -> #N/A | K78: =NA() -> #N/A
A79: 59 | B79: =RAND() -> 0.87479516 | C79: =IF(E79=1,_xlfn.NORM.INV(RAND(),$D$4,$G$4),_xlfn.NORM.INV(RAND(),$D$14,$G$14)) -> 3.5100407 | D79: =IF(E79=1,_xlfn.NORM.INV(RAND(),$D$5-$L$4/$K$4*(C79-$D$4),SQRT(1/(2*$K$4))),_xlfn.NORM.INV(RAND(),$D$15-$L$14/$K$14*(C79-$D$14),SQRT(1/(2*$K$14)))) -> 2.883006 | E79: =IF(B79<$H$1,1,2) -> 2 | F79: =IF($E79=1,D79,NA()) -> #N/A | G79: =IF($E79=2,D79,NA()) -> 2.883006 | H79: =NA() -> #N/A | I79: =NA() -> #N/A | J79: =NA() -> #N/A | K79: =NA() -> #N/A
A80: 60 | B80: =RAND() -> 0.38888434 | C80: =IF(E80=1,_xlfn.NORM.INV(RAND(),$D$4,$G$4),_xlfn.NORM.INV(RAND(),$D$14,$G$14)) -> 1.3614527 | D80: =IF(E80=1,_xlfn.NORM.INV(RAND(),$D$5-$L$4/$K$4*(C80-$D$4),SQRT(1/(2*$K$4))),_xlfn.NORM.INV(RAND(),$D$15-$L$14/$K$14*(C80-$D$14),SQRT(1/(2*$K$14)))) -> 0.11329178 | E80: =IF(B80<$H$1,1,2) -> 1 | F80: =IF($E80=1,D80,NA()) -> 0.11329178 | G80: =IF($E80=2,D80,NA()) -> #N/A | H80: =NA() -> #N/A | I80: =NA() -> #N/A | J80: =NA() -> #N/A | K80: =NA() -> #N/A
A81: 61 | B81: =RAND() -> 0.18723707 | C81: =IF(E81=1,_xlfn.NORM.INV(RAND(),$D$4,$G$4),_xlfn.NORM.INV(RAND(),$D$14,$G$14)) -> -0.59891529 | D81: =IF(E81=1,_xlfn.NORM.INV(RAND(),$D$5-$L$4/$K$4*(C81-$D$4),SQRT(1/(2*$K$4))),_xlfn.NORM.INV(RAND(),$D$15-$L$14/$K$14*(C81-$D$14),SQRT(1/(2*$K$14)))) -> 1.6283394 | E81: =IF(B81<$H$1,1,2) -> 1 | F81: =IF($E81=1,D81,NA()) -> 1.6283394 | G81: =IF($E81=2,D81,NA()) -> #N/A | H81: =NA() -> #N/A | I81: =NA() -> #N/A | J81: =NA() -> #N/A | K81: =NA() -> #N/A
...
